<?xml version="1.0" encoding="utf-8"?>
<!-- This URDF was automatically created by SolidWorks to URDF Exporter! Originally created by Stephen Brawner (brawner@gmail.com) 
     Commit Version: 1.6.0-4-g7f85cfe  Build Version: 1.6.7995.38578
     For more information, please see http://wiki.ros.org/sw_urdf_exporter -->
<robot
  name="arduino_car">
  <link
    name="base_link">
    <inertial>
      <origin
        xyz="-3.46944695195361E-18 3.68628738645072E-18 -0.00127"
        rpy="0 0 0" />
      <mass
        value="0.0569877915381237" />
      <inertia
        ixx="7.84770351241839E-05"
        ixy="-3.14208108330272E-10"
        ixz="2.78489323288408E-23"
        iyy="0.000171152712170539"
        iyz="-1.25259373056998E-22"
        izz="0.000249568470222075" />
    </inertial>
    <visual>
      <origin
        xyz="0 0 0"
        rpy="0 0 0" />
      <geometry>
        <mesh
          filename="package://arduino_car/meshes/base_link.STL" />
      </geometry>
      <material
        name="">
        <color
          rgba="0.792156862745098 0.819607843137255 0.933333333333333 1" />
      </material>
    </visual>
    <collision>
      <origin
        xyz="0 0 0"
        rpy="0 0 0" />
      <geometry>
        <mesh
          filename="package://arduino_car/meshes/base_link.STL" />
      </geometry>
    </collision>
  </link>
  <link
    name="left_actuator">
    <inertial>
      <origin
        xyz="-0.000504660947662716 -0.0107819464387979 3.46944695195361E-18"
        rpy="0 0 0" />
      <mass
        value="0.262946440650313" />
      <inertia
        ixx="2.19436701171615E-05"
        ixy="5.79687599956981E-07"
        ixz="3.28905755052471E-21"
        iyy="0.000140790157888514"
        iyz="-1.63578083145561E-21"
        izz="0.000140042263239691" />
    </inertial>
    <visual>
      <origin
        xyz="0 0 0"
        rpy="0 0 0" />
      <geometry>
        <mesh
          filename="package://arduino_car/meshes/left_actuator.STL" />
      </geometry>
      <material
        name="">
        <color
          rgba="0.647058823529412 0.619607843137255 0.588235294117647 1" />
      </material>
    </visual>
    <collision>
      <origin
        xyz="0 0 0"
        rpy="0 0 0" />
      <geometry>
        <mesh
          filename="package://arduino_car/meshes/left_actuator.STL" />
      </geometry>
    </collision>
  </link>
  <joint
    name="joint_left_actuator"
    type="fixed">
    <origin
      xyz="0.0050554 0.06096 -0.022225"
      rpy="0 0 0" />
    <parent
      link="base_link" />
    <child
      link="left_actuator" />
    <axis
      xyz="0 0 0" />
  </joint>
  <link
    name="left_wheel">
    <inertial>
      <origin
        xyz="-4.33680868994202E-18 -0.0126828683664394 -8.67361737988404E-19"
        rpy="0 0 0" />
      <mass
        value="0.0868235158113897" />
      <inertia
        ixx="2.83793049666763E-05"
        ixy="1.05613339744524E-20"
        ixz="-1.80592313751731E-37"
        iyy="4.74303737916179E-05"
        iyz="-7.09232262622493E-38"
        izz="2.83793049666763E-05" />
    </inertial>
    <visual>
      <origin
        xyz="0 0 0"
        rpy="0 0 0" />
      <geometry>
        <mesh
          filename="package://arduino_car/meshes/left_wheel.STL" />
      </geometry>
      <material
        name="">
        <color
          rgba="0.792156862745098 0.819607843137255 0.933333333333333 1" />
      </material>
    </visual>
    <collision>
      <origin
        xyz="0 0 0"
        rpy="0 0 0" />
      <geometry>
        <mesh
          filename="package://arduino_car/meshes/left_wheel.STL" />
      </geometry>
    </collision>
  </link>
  <joint
    name="joint_left_wheel"
    type="continuous">
    <origin
      xyz="-0.029303 0.02794 0"
      rpy="0 0 0" />
    <parent
      link="left_actuator" />
    <child
      link="left_wheel" />
    <axis
      xyz="0 1 0" />
    <limit
      effort="1"
      velocity="1" />
  </joint>
  <link
    name="right_actuator">
    <inertial>
      <origin
        xyz="-0.000504660947662709 0.0107819464387979 -1.73472347597681E-18"
        rpy="0 0 0" />
      <mass
        value="0.262946440650313" />
      <inertia
        ixx="2.19436701171615E-05"
        ixy="-5.79687599956873E-07"
        ixz="-2.49863060555046E-22"
        iyy="0.000140790157888514"
        iyz="1.16363163568489E-21"
        izz="0.000140042263239691" />
    </inertial>
    <visual>
      <origin
        xyz="0 0 0"
        rpy="0 0 0" />
      <geometry>
        <mesh
          filename="package://arduino_car/meshes/right_actuator.STL" />
      </geometry>
      <material
        name="">
        <color
          rgba="0.647058823529412 0.619607843137255 0.588235294117647 1" />
      </material>
    </visual>
    <collision>
      <origin
        xyz="0 0 0"
        rpy="0 0 0" />
      <geometry>
        <mesh
          filename="package://arduino_car/meshes/right_actuator.STL" />
      </geometry>
    </collision>
  </link>
  <joint
    name="joint_right_actuator"
    type="fixed">
    <origin
      xyz="0.00505543453695816 -0.06096 -0.022225"
      rpy="0 0 0" />
    <parent
      link="base_link" />
    <child
      link="right_actuator" />
    <axis
      xyz="0 0 0" />
  </joint>
  <link
    name="right_wheel">
    <inertial>
      <origin
        xyz="3.46944695195361E-18 0.0126828683664394 -2.60208521396521E-18"
        rpy="0 0 0" />
      <mass
        value="0.0868235158113896" />
      <inertia
        ixx="2.83793049666763E-05"
        ixy="1.0880344281002E-20"
        ixz="-2.03445428163645E-21"
        iyy="4.74303737916179E-05"
        iyz="-7.52199855790826E-22"
        izz="2.83793049666763E-05" />
    </inertial>
    <visual>
      <origin
        xyz="0 0 0"
        rpy="0 0 0" />
      <geometry>
        <mesh
          filename="package://arduino_car/meshes/right_wheel.STL" />
      </geometry>
      <material
        name="">
        <color
          rgba="0.792156862745098 0.819607843137255 0.933333333333333 1" />
      </material>
    </visual>
    <collision>
      <origin
        xyz="0 0 0"
        rpy="0 0 0" />
      <geometry>
        <mesh
          filename="package://arduino_car/meshes/right_wheel.STL" />
      </geometry>
    </collision>
  </link>
  <joint
    name="joint_left_wheel"
    type="revolute">
    <origin
      xyz="-0.029303 -0.02794 0"
      rpy="0 0 0" />
    <parent
      link="right_actuator" />
    <child
      link="right_wheel" />
    <axis
      xyz="0 -1 0" />
    <limit
      lower="0"
      upper="0"
      effort="1"
      velocity="1" />
  </joint>
</robot>